Workbook

Sheet Read me
A1: Risk register layer - EU AI Act evidence crosswalk
A2: Every risk row must cite a Linked Crosswalk Obligation ID. Actor role, risk tier and the ISO 42001 verdict are looked up from the crosswalk by formula.
A3: 'Risk' is scored twice: Rights Impact (harm to health, safety and fundamental rights of persons - the Act's sense) and Organisational Impact (harm to the organisation - the enterprise-risk sense). They do not always point the same way.
A4: Grey columns are formulas - do not overwrite. Scales, effectiveness caps, bands and limitations are on the 'Scoring Methodology' sheet.
A5: Rows RISK-001 and RISK-002 are ILLUSTRATIVE worked examples about fictional systems. Evidence references are placeholders, not real documents.
A6: Dates were set relative to 2 Oct 2026 and to the application dates in the crosswalk (as of 2 Oct 2026; subject to further legislative amendment).

Sheet Register
A1: Risk ID | B1: Linked Crosswalk Obligation ID | C1: AI System / Use Case | D1: Actor Role (auto) | E1: Risk Tier (auto) | F1: Risk Description | G1: Affected Party (individuals / org / both) | H1: Likelihood (1-5) | I1: Rights Impact (1-5) | J1: Organisational Impact (1-5) | K1: Rights Impact (L x I) | L1: Organisational Impact (L x I) | M1: Inherent Score | N1: Score driver | O1: Existing Controls (ISO 42001 ref) | P1: Crosswalk ISO 42001 verdict (auto) | Q1: Control Effectiveness (as rated) | R1: Effectiveness cap from verdict (auto) | S1: Override justification (non-ISO control) | T1: Effectiveness applied | U1: Residual Likelihood | V1: Residual Rights (L x I) | W1: Residual Org (L x I) | X1: Residual Score | Y1: Residual band | Z1: Risk Owner (role) | AA1: Treatment Decision | AB1: Target Date | AC1: Evidence Reference | AD1: Review Date
A2: RISK-001 | B2: PRV-HR-A10-BIAS | C2: EXAMPLE (fictional): recruitment CV-screening and candidate-ranking tool sold to employers (Annex III 4(a)). | D2: =IF(B2="","",IFERROR(INDEX('Crosswalk IDs'!$C$2:$C$47,MATCH(B2,'Crosswalk IDs'!$A$2:$A$47,0)),"ID NOT IN CROSSWALK")) -> Provider | E2: =IF(B2="","",IFERROR(INDEX('Crosswalk IDs'!$D$2:$D$47,MATCH(B2,'Crosswalk IDs'!$A$2:$A$47,0)),"ID NOT IN CROSSWALK")) -> High-risk | F2: Training and validation data under-represent candidates with career breaks and some demographic groups, so ranking systematically scores them lower. Non-conformity with Art. 10(2)(f)-(g) and 10(3)-(4); outcome is discrimination in access to employment. | G2: both | H2: 3 | I2: 4 | J2: 3 | K2: =IF(OR(H2="",I2=""),"",H2*I2) -> 12 | L2: =IF(OR(H2="",J2=""),"",H2*J2) -> 9 | M2: =IF(K2="","",MAX(K2,L2)) -> 12 | N2: =IF(M2="","",IF(K2>L2,"Rights",IF(L2>K2,"Organisation","Both equal"))) -> Rights | O2: A.7.4 Quality of data; A.5.4 Impact on individuals or groups; A.6.2.4 Verification and validation. | P2: =IF(B2="","",IFERROR(INDEX('Crosswalk IDs'!$E$2:$E$47,MATCH(B2,'Crosswalk IDs'!$A$2:$A$47,0)),"ID NOT IN CROSSWALK")) -> Partially evidences | Q2: Partially effective | R2: =IF(P2="","",IFERROR(INDEX(Lists!$F$2:$F$5,MATCH(P2,Lists!$E$2:$E$5,0)),"")) -> Partially effective | T2: =IF(OR(Q2="",R2=""),"",IF(AND(MATCH(Q2,Lists!$A$2:$A$4,0)>MATCH(R2,Lists!$A$2:$A$4,0),S2=""),R2,Q2)) -> Partially effective | U2: =IF(T2="","",MAX(1,H2-(MATCH(T2,Lists!$A$2:$A$4,0)-1))) -> 2 | V2: =IF(U2="","",U2*I2) -> 8 | W2: =IF(U2="","",U2*J2) -> 6 | X2: =IF(U2="","",MAX(V2,W2)) -> 8 | Y2: =IF(X2="","",CHOOSE(MAX(IF(X2>=16,4,IF(X2>=10,3,IF(X2>=5,2,1))),IF(OR(I2=5,AND(I2>=4,U2>=2)),3,1)),"Low","Medium","High","Critical")) -> High | Z2: Head of AI Product (accountable); Chief Data Officer (responsible); DPO (consulted) | AA2: Mitigate | AB2: 46568 | AC2: EV-A10-BIAS-001 (placeholder): bias evaluation report v1.2 - run once on gender only; no test on employment gaps; no re-test cadence. | AD2: 46402
A3: RISK-002 | B3: GPP-GP-A53-COPY | C3: EXAMPLE (fictional): general-purpose language model offered to downstream providers through an API. | D3: =IF(B3="","",IFERROR(INDEX('Crosswalk IDs'!$C$2:$C$47,MATCH(B3,'Crosswalk IDs'!$A$2:$A$47,0)),"ID NOT IN CROSSWALK")) -> GPAI model provider | E3: =IF(B3="","",IFERROR(INDEX('Crosswalk IDs'!$D$2:$D$47,MATCH(B3,'Crosswalk IDs'!$A$2:$A$47,0)),"ID NOT IN CROSSWALK")) -> GPAI | F3: Data-acquisition pipeline does not reliably detect or honour machine-readable rights reservations (Art. 4(3), Directive (EU) 2019/790), so reserved works enter training data and the Art. 53(1)(c) copyright policy cannot be evidenced to the AI Office. | G3: both | H3: 3 | I3: 2 | J3: 4 | K3: =IF(OR(H3="",I3=""),"",H3*I3) -> 6 | L3: =IF(OR(H3="",J3=""),"",H3*J3) -> 12 | M3: =IF(K3="","",MAX(K3,L3)) -> 12 | N3: =IF(M3="","",IF(K3>L3,"Rights",IF(L3>K3,"Organisation","Both equal"))) -> Organisation | O3: A.7.3 Acquisition of data; A.7.5 Data provenance (these give provenance records but do not address rights reservations). | P3: =IF(B3="","",IFERROR(INDEX('Crosswalk IDs'!$E$2:$E$47,MATCH(B3,'Crosswalk IDs'!$A$2:$A$47,0)),"ID NOT IN CROSSWALK")) -> Adjacent | Q3: Partially effective | R3: =IF(P3="","",IFERROR(INDEX(Lists!$F$2:$F$5,MATCH(P3,Lists!$E$2:$E$5,0)),"")) -> Not effective | S3: Non-ISO control: opt-out detection filter in the crawler with a monthly sampled test log. Bespoke technical control, not an ISO 42001 control; test log is the evidence. | T3: =IF(OR(Q3="",R3=""),"",IF(AND(MATCH(Q3,Lists!$A$2:$A$4,0)>MATCH(R3,Lists!$A$2:$A$4,0),S3=""),R3,Q3)) -> Partially effective | U3: =IF(T3="","",MAX(1,H3-(MATCH(T3,Lists!$A$2:$A$4,0)-1))) -> 2 | V3: =IF(U3="","",U3*I3) -> 4 | W3: =IF(U3="","",U3*J3) -> 8 | X3: =IF(U3="","",MAX(V3,W3)) -> 8 | Y3: =IF(X3="","",CHOOSE(MAX(IF(X3>=16,4,IF(X3>=10,3,IF(X3>=5,2,1))),IF(OR(I3=5,AND(I3>=4,U3>=2)),3,1)),"Low","Medium","High","Critical")) -> Medium | Z3: General Counsel (accountable); Head of Data Acquisition (responsible) | AA3: Mitigate | AB3: 46387 | AC3: EV-A53-COPY-001 (placeholder): crawler opt-out filter test log. | AD3: 46341
D4: =IF(B4="","",IFERROR(INDEX('Crosswalk IDs'!$C$2:$C$47,MATCH(B4,'Crosswalk IDs'!$A$2:$A$47,0)),"ID NOT IN CROSSWALK")) | E4: =IF(B4="","",IFERROR(INDEX('Crosswalk IDs'!$D$2:$D$47,MATCH(B4,'Crosswalk IDs'!$A$2:$A$47,0)),"ID NOT IN CROSSWALK")) | K4: =IF(OR(H4="",I4=""),"",H4*I4) | L4: =IF(OR(H4="",J4=""),"",H4*J4) | M4: =IF(K4="","",MAX(K4,L4)) | N4: =IF(M4="","",IF(K4>L4,"Rights",IF(L4>K4,"Organisation","Both equal"))) | P4: =IF(B4="","",IFERROR(INDEX('Crosswalk IDs'!$E$2:$E$47,MATCH(B4,'Crosswalk IDs'!$A$2:$A$47,0)),"ID NOT IN CROSSWALK")) | R4: =IF(P4="","",IFERROR(INDEX(Lists!$F$2:$F$5,MATCH(P4,Lists!$E$2:$E$5,0)),"")) | T4: =IF(OR(Q4="",R4=""),"",IF(AND(MATCH(Q4,Lists!$A$2:$A$4,0)>MATCH(R4,Lists!$A$2:$A$4,0),S4=""),R4,Q4)) | U4: =IF(T4="","",MAX(1,H4-(MATCH(T4,Lists!$A$2:$A$4,0)-1))) | V4: =IF(U4="","",U4*I4) | W4: =IF(U4="","",U4*J4) | X4: =IF(U4="","",MAX(V4,W4)) | Y4: =IF(X4="","",CHOOSE(MAX(IF(X4>=16,4,IF(X4>=10,3,IF(X4>=5,2,1))),IF(OR(I4=5,AND(I4>=4,U4>=2)),3,1)),"Low","Medium","High","Critical"))
D5: =IF(B5="","",IFERROR(INDEX('Crosswalk IDs'!$C$2:$C$47,MATCH(B5,'Crosswalk IDs'!$A$2:$A$47,0)),"ID NOT IN CROSSWALK")) | E5: =IF(B5="","",IFERROR(INDEX('Crosswalk IDs'!$D$2:$D$47,MATCH(B5,'Crosswalk IDs'!$A$2:$A$47,0)),"ID NOT IN CROSSWALK")) | K5: =IF(OR(H5="",I5=""),"",H5*I5) | L5: =IF(OR(H5="",J5=""),"",H5*J5) | M5: =IF(K5="","",MAX(K5,L5)) | N5: =IF(M5="","",IF(K5>L5,"Rights",IF(L5>K5,"Organisation","Both equal"))) | P5: =IF(B5="","",IFERROR(INDEX('Crosswalk IDs'!$E$2:$E$47,MATCH(B5,'Crosswalk IDs'!$A$2:$A$47,0)),"ID NOT IN CROSSWALK")) | R5: =IF(P5="","",IFERROR(INDEX(Lists!$F$2:$F$5,MATCH(P5,Lists!$E$2:$E$5,0)),"")) | T5: =IF(OR(Q5="",R5=""),"",IF(AND(MATCH(Q5,Lists!$A$2:$A$4,0)>MATCH(R5,Lists!$A$2:$A$4,0),S5=""),R5,Q5)) | U5: =IF(T5="","",MAX(1,H5-(MATCH(T5,Lists!$A$2:$A$4,0)-1))) | V5: =IF(U5="","",U5*I5) | W5: =IF(U5="","",U5*J5) | X5: =IF(U5="","",MAX(V5,W5)) | Y5: =IF(X5="","",CHOOSE(MAX(IF(X5>=16,4,IF(X5>=10,3,IF(X5>=5,2,1))),IF(OR(I5=5,AND(I5>=4,U5>=2)),3,1)),"Low","Medium","High","Critical"))
D6: =IF(B6="","",IFERROR(INDEX('Crosswalk IDs'!$C$2:$C$47,MATCH(B6,'Crosswalk IDs'!$A$2:$A$47,0)),"ID NOT IN CROSSWALK")) | E6: =IF(B6="","",IFERROR(INDEX('Crosswalk IDs'!$D$2:$D$47,MATCH(B6,'Crosswalk IDs'!$A$2:$A$47,0)),"ID NOT IN CROSSWALK")) | K6: =IF(OR(H6="",I6=""),"",H6*I6) | L6: =IF(OR(H6="",J6=""),"",H6*J6) | M6: =IF(K6="","",MAX(K6,L6)) | N6: =IF(M6="","",IF(K6>L6,"Rights",IF(L6>K6,"Organisation","Both equal"))) | P6: =IF(B6="","",IFERROR(INDEX('Crosswalk IDs'!$E$2:$E$47,MATCH(B6,'Crosswalk IDs'!$A$2:$A$47,0)),"ID NOT IN CROSSWALK")) | R6: =IF(P6="","",IFERROR(INDEX(Lists!$F$2:$F$5,MATCH(P6,Lists!$E$2:$E$5,0)),"")) | T6: =IF(OR(Q6="",R6=""),"",IF(AND(MATCH(Q6,Lists!$A$2:$A$4,0)>MATCH(R6,Lists!$A$2:$A$4,0),S6=""),R6,Q6)) | U6: =IF(T6="","",MAX(1,H6-(MATCH(T6,Lists!$A$2:$A$4,0)-1))) | V6: =IF(U6="","",U6*I6) | W6: =IF(U6="","",U6*J6) | X6: =IF(U6="","",MAX(V6,W6)) | Y6: =IF(X6="","",CHOOSE(MAX(IF(X6>=16,4,IF(X6>=10,3,IF(X6>=5,2,1))),IF(OR(I6=5,AND(I6>=4,U6>=2)),3,1)),"Low","Medium","High","Critical"))
D7: =IF(B7="","",IFERROR(INDEX('Crosswalk IDs'!$C$2:$C$47,MATCH(B7,'Crosswalk IDs'!$A$2:$A$47,0)),"ID NOT IN CROSSWALK")) | E7: =IF(B7="","",IFERROR(INDEX('Crosswalk IDs'!$D$2:$D$47,MATCH(B7,'Crosswalk IDs'!$A$2:$A$47,0)),"ID NOT IN CROSSWALK")) | K7: =IF(OR(H7="",I7=""),"",H7*I7) | L7: =IF(OR(H7="",J7=""),"",H7*J7) | M7: =IF(K7="","",MAX(K7,L7)) | N7: =IF(M7="","",IF(K7>L7,"Rights",IF(L7>K7,"Organisation","Both equal"))) | P7: =IF(B7="","",IFERROR(INDEX('Crosswalk IDs'!$E$2:$E$47,MATCH(B7,'Crosswalk IDs'!$A$2:$A$47,0)),"ID NOT IN CROSSWALK")) | R7: =IF(P7="","",IFERROR(INDEX(Lists!$F$2:$F$5,MATCH(P7,Lists!$E$2:$E$5,0)),"")) | T7: =IF(OR(Q7="",R7=""),"",IF(AND(MATCH(Q7,Lists!$A$2:$A$4,0)>MATCH(R7,Lists!$A$2:$A$4,0),S7=""),R7,Q7)) | U7: =IF(T7="","",MAX(1,H7-(MATCH(T7,Lists!$A$2:$A$4,0)-1))) | V7: =IF(U7="","",U7*I7) | W7: =IF(U7="","",U7*J7) | X7: =IF(U7="","",MAX(V7,W7)) | Y7: =IF(X7="","",CHOOSE(MAX(IF(X7>=16,4,IF(X7>=10,3,IF(X7>=5,2,1))),IF(OR(I7=5,AND(I7>=4,U7>=2)),3,1)),"Low","Medium","High","Critical"))
D8: =IF(B8="","",IFERROR(INDEX('Crosswalk IDs'!$C$2:$C$47,MATCH(B8,'Crosswalk IDs'!$A$2:$A$47,0)),"ID NOT IN CROSSWALK")) | E8: =IF(B8="","",IFERROR(INDEX('Crosswalk IDs'!$D$2:$D$47,MATCH(B8,'Crosswalk IDs'!$A$2:$A$47,0)),"ID NOT IN CROSSWALK")) | K8: =IF(OR(H8="",I8=""),"",H8*I8) | L8: =IF(OR(H8="",J8=""),"",H8*J8) | M8: =IF(K8="","",MAX(K8,L8)) | N8: =IF(M8="","",IF(K8>L8,"Rights",IF(L8>K8,"Organisation","Both equal"))) | P8: =IF(B8="","",IFERROR(INDEX('Crosswalk IDs'!$E$2:$E$47,MATCH(B8,'Crosswalk IDs'!$A$2:$A$47,0)),"ID NOT IN CROSSWALK")) | R8: =IF(P8="","",IFERROR(INDEX(Lists!$F$2:$F$5,MATCH(P8,Lists!$E$2:$E$5,0)),"")) | T8: =IF(OR(Q8="",R8=""),"",IF(AND(MATCH(Q8,Lists!$A$2:$A$4,0)>MATCH(R8,Lists!$A$2:$A$4,0),S8=""),R8,Q8)) | U8: =IF(T8="","",MAX(1,H8-(MATCH(T8,Lists!$A$2:$A$4,0)-1))) | V8: =IF(U8="","",U8*I8) | W8: =IF(U8="","",U8*J8) | X8: =IF(U8="","",MAX(V8,W8)) | Y8: =IF(X8="","",CHOOSE(MAX(IF(X8>=16,4,IF(X8>=10,3,IF(X8>=5,2,1))),IF(OR(I8=5,AND(I8>=4,U8>=2)),3,1)),"Low","Medium","High","Critical"))
D9: =IF(B9="","",IFERROR(INDEX('Crosswalk IDs'!$C$2:$C$47,MATCH(B9,'Crosswalk IDs'!$A$2:$A$47,0)),"ID NOT IN CROSSWALK")) | E9: =IF(B9="","",IFERROR(INDEX('Crosswalk IDs'!$D$2:$D$47,MATCH(B9,'Crosswalk IDs'!$A$2:$A$47,0)),"ID NOT IN CROSSWALK")) | K9: =IF(OR(H9="",I9=""),"",H9*I9) | L9: =IF(OR(H9="",J9=""),"",H9*J9) | M9: =IF(K9="","",MAX(K9,L9)) | N9: =IF(M9="","",IF(K9>L9,"Rights",IF(L9>K9,"Organisation","Both equal"))) | P9: =IF(B9="","",IFERROR(INDEX('Crosswalk IDs'!$E$2:$E$47,MATCH(B9,'Crosswalk IDs'!$A$2:$A$47,0)),"ID NOT IN CROSSWALK")) | R9: =IF(P9="","",IFERROR(INDEX(Lists!$F$2:$F$5,MATCH(P9,Lists!$E$2:$E$5,0)),"")) | T9: =IF(OR(Q9="",R9=""),"",IF(AND(MATCH(Q9,Lists!$A$2:$A$4,0)>MATCH(R9,Lists!$A$2:$A$4,0),S9=""),R9,Q9)) | U9: =IF(T9="","",MAX(1,H9-(MATCH(T9,Lists!$A$2:$A$4,0)-1))) | V9: =IF(U9="","",U9*I9) | W9: =IF(U9="","",U9*J9) | X9: =IF(U9="","",MAX(V9,W9)) | Y9: =IF(X9="","",CHOOSE(MAX(IF(X9>=16,4,IF(X9>=10,3,IF(X9>=5,2,1))),IF(OR(I9=5,AND(I9>=4,U9>=2)),3,1)),"Low","Medium","High","Critical"))
D10: =IF(B10="","",IFERROR(INDEX('Crosswalk IDs'!$C$2:$C$47,MATCH(B10,'Crosswalk IDs'!$A$2:$A$47,0)),"ID NOT IN CROSSWALK")) | E10: =IF(B10="","",IFERROR(INDEX('Crosswalk IDs'!$D$2:$D$47,MATCH(B10,'Crosswalk IDs'!$A$2:$A$47,0)),"ID NOT IN CROSSWALK")) | K10: =IF(OR(H10="",I10=""),"",H10*I10) | L10: =IF(OR(H10="",J10=""),"",H10*J10) | M10: =IF(K10="","",MAX(K10,L10)) | N10: =IF(M10="","",IF(K10>L10,"Rights",IF(L10>K10,"Organisation","Both equal"))) | P10: =IF(B10="","",IFERROR(INDEX('Crosswalk IDs'!$E$2:$E$47,MATCH(B10,'Crosswalk IDs'!$A$2:$A$47,0)),"ID NOT IN CROSSWALK")) | R10: =IF(P10="","",IFERROR(INDEX(Lists!$F$2:$F$5,MATCH(P10,Lists!$E$2:$E$5,0)),"")) | T10: =IF(OR(Q10="",R10=""),"",IF(AND(MATCH(Q10,Lists!$A$2:$A$4,0)>MATCH(R10,Lists!$A$2:$A$4,0),S10=""),R10,Q10)) | U10: =IF(T10="","",MAX(1,H10-(MATCH(T10,Lists!$A$2:$A$4,0)-1))) | V10: =IF(U10="","",U10*I10) | W10: =IF(U10="","",U10*J10) | X10: =IF(U10="","",MAX(V10,W10)) | Y10: =IF(X10="","",CHOOSE(MAX(IF(X10>=16,4,IF(X10>=10,3,IF(X10>=5,2,1))),IF(OR(I10=5,AND(I10>=4,U10>=2)),3,1)),"Low","Medium","High","Critical"))
D11: =IF(B11="","",IFERROR(INDEX('Crosswalk IDs'!$C$2:$C$47,MATCH(B11,'Crosswalk IDs'!$A$2:$A$47,0)),"ID NOT IN CROSSWALK")) | E11: =IF(B11="","",IFERROR(INDEX('Crosswalk IDs'!$D$2:$D$47,MATCH(B11,'Crosswalk IDs'!$A$2:$A$47,0)),"ID NOT IN CROSSWALK")) | K11: =IF(OR(H11="",I11=""),"",H11*I11) | L11: =IF(OR(H11="",J11=""),"",H11*J11) | M11: =IF(K11="","",MAX(K11,L11)) | N11: =IF(M11="","",IF(K11>L11,"Rights",IF(L11>K11,"Organisation","Both equal"))) | P11: =IF(B11="","",IFERROR(INDEX('Crosswalk IDs'!$E$2:$E$47,MATCH(B11,'Crosswalk IDs'!$A$2:$A$47,0)),"ID NOT IN CROSSWALK")) | R11: =IF(P11="","",IFERROR(INDEX(Lists!$F$2:$F$5,MATCH(P11,Lists!$E$2:$E$5,0)),"")) | T11: =IF(OR(Q11="",R11=""),"",IF(AND(MATCH(Q11,Lists!$A$2:$A$4,0)>MATCH(R11,Lists!$A$2:$A$4,0),S11=""),R11,Q11)) | U11: =IF(T11="","",MAX(1,H11-(MATCH(T11,Lists!$A$2:$A$4,0)-1))) | V11: =IF(U11="","",U11*I11) | W11: =IF(U11="","",U11*J11) | X11: =IF(U11="","",MAX(V11,W11)) | Y11: =IF(X11="","",CHOOSE(MAX(IF(X11>=16,4,IF(X11>=10,3,IF(X11>=5,2,1))),IF(OR(I11=5,AND(I11>=4,U11>=2)),3,1)),"Low","Medium","High","Critical"))
D12: =IF(B12="","",IFERROR(INDEX('Crosswalk IDs'!$C$2:$C$47,MATCH(B12,'Crosswalk IDs'!$A$2:$A$47,0)),"ID NOT IN CROSSWALK")) | E12: =IF(B12="","",IFERROR(INDEX('Crosswalk IDs'!$D$2:$D$47,MATCH(B12,'Crosswalk IDs'!$A$2:$A$47,0)),"ID NOT IN CROSSWALK")) | K12: =IF(OR(H12="",I12=""),"",H12*I12) | L12: =IF(OR(H12="",J12=""),"",H12*J12) | M12: =IF(K12="","",MAX(K12,L12)) | N12: =IF(M12="","",IF(K12>L12,"Rights",IF(L12>K12,"Organisation","Both equal"))) | P12: =IF(B12="","",IFERROR(INDEX('Crosswalk IDs'!$E$2:$E$47,MATCH(B12,'Crosswalk IDs'!$A$2:$A$47,0)),"ID NOT IN CROSSWALK")) | R12: =IF(P12="","",IFERROR(INDEX(Lists!$F$2:$F$5,MATCH(P12,Lists!$E$2:$E$5,0)),"")) | T12: =IF(OR(Q12="",R12=""),"",IF(AND(MATCH(Q12,Lists!$A$2:$A$4,0)>MATCH(R12,Lists!$A$2:$A$4,0),S12=""),R12,Q12)) | U12: =IF(T12="","",MAX(1,H12-(MATCH(T12,Lists!$A$2:$A$4,0)-1))) | V12: =IF(U12="","",U12*I12) | W12: =IF(U12="","",U12*J12) | X12: =IF(U12="","",MAX(V12,W12)) | Y12: =IF(X12="","",CHOOSE(MAX(IF(X12>=16,4,IF(X12>=10,3,IF(X12>=5,2,1))),IF(OR(I12=5,AND(I12>=4,U12>=2)),3,1)),"Low","Medium","High","Critical"))
D13: =IF(B13="","",IFERROR(INDEX('Crosswalk IDs'!$C$2:$C$47,MATCH(B13,'Crosswalk IDs'!$A$2:$A$47,0)),"ID NOT IN CROSSWALK")) | E13: =IF(B13="","",IFERROR(INDEX('Crosswalk IDs'!$D$2:$D$47,MATCH(B13,'Crosswalk IDs'!$A$2:$A$47,0)),"ID NOT IN CROSSWALK")) | K13: =IF(OR(H13="",I13=""),"",H13*I13) | L13: =IF(OR(H13="",J13=""),"",H13*J13) | M13: =IF(K13="","",MAX(K13,L13)) | N13: =IF(M13="","",IF(K13>L13,"Rights",IF(L13>K13,"Organisation","Both equal"))) | P13: =IF(B13="","",IFERROR(INDEX('Crosswalk IDs'!$E$2:$E$47,MATCH(B13,'Crosswalk IDs'!$A$2:$A$47,0)),"ID NOT IN CROSSWALK")) | R13: =IF(P13="","",IFERROR(INDEX(Lists!$F$2:$F$5,MATCH(P13,Lists!$E$2:$E$5,0)),"")) | T13: =IF(OR(Q13="",R13=""),"",IF(AND(MATCH(Q13,Lists!$A$2:$A$4,0)>MATCH(R13,Lists!$A$2:$A$4,0),S13=""),R13,Q13)) | U13: =IF(T13="","",MAX(1,H13-(MATCH(T13,Lists!$A$2:$A$4,0)-1))) | V13: =IF(U13="","",U13*I13) | W13: =IF(U13="","",U13*J13) | X13: =IF(U13="","",MAX(V13,W13)) | Y13: =IF(X13="","",CHOOSE(MAX(IF(X13>=16,4,IF(X13>=10,3,IF(X13>=5,2,1))),IF(OR(I13=5,AND(I13>=4,U13>=2)),3,1)),"Low","Medium","High","Critical"))
D14: =IF(B14="","",IFERROR(INDEX('Crosswalk IDs'!$C$2:$C$47,MATCH(B14,'Crosswalk IDs'!$A$2:$A$47,0)),"ID NOT IN CROSSWALK")) | E14: =IF(B14="","",IFERROR(INDEX('Crosswalk IDs'!$D$2:$D$47,MATCH(B14,'Crosswalk IDs'!$A$2:$A$47,0)),"ID NOT IN CROSSWALK")) | K14: =IF(OR(H14="",I14=""),"",H14*I14) | L14: =IF(OR(H14="",J14=""),"",H14*J14) | M14: =IF(K14="","",MAX(K14,L14)) | N14: =IF(M14="","",IF(K14>L14,"Rights",IF(L14>K14,"Organisation","Both equal"))) | P14: =IF(B14="","",IFERROR(INDEX('Crosswalk IDs'!$E$2:$E$47,MATCH(B14,'Crosswalk IDs'!$A$2:$A$47,0)),"ID NOT IN CROSSWALK")) | R14: =IF(P14="","",IFERROR(INDEX(Lists!$F$2:$F$5,MATCH(P14,Lists!$E$2:$E$5,0)),"")) | T14: =IF(OR(Q14="",R14=""),"",IF(AND(MATCH(Q14,Lists!$A$2:$A$4,0)>MATCH(R14,Lists!$A$2:$A$4,0),S14=""),R14,Q14)) | U14: =IF(T14="","",MAX(1,H14-(MATCH(T14,Lists!$A$2:$A$4,0)-1))) | V14: =IF(U14="","",U14*I14) | W14: =IF(U14="","",U14*J14) | X14: =IF(U14="","",MAX(V14,W14)) | Y14: =IF(X14="","",CHOOSE(MAX(IF(X14>=16,4,IF(X14>=10,3,IF(X14>=5,2,1))),IF(OR(I14=5,AND(I14>=4,U14>=2)),3,1)),"Low","Medium","High","Critical"))
D15: =IF(B15="","",IFERROR(INDEX('Crosswalk IDs'!$C$2:$C$47,MATCH(B15,'Crosswalk IDs'!$A$2:$A$47,0)),"ID NOT IN CROSSWALK")) | E15: =IF(B15="","",IFERROR(INDEX('Crosswalk IDs'!$D$2:$D$47,MATCH(B15,'Crosswalk IDs'!$A$2:$A$47,0)),"ID NOT IN CROSSWALK")) | K15: =IF(OR(H15="",I15=""),"",H15*I15) | L15: =IF(OR(H15="",J15=""),"",H15*J15) | M15: =IF(K15="","",MAX(K15,L15)) | N15: =IF(M15="","",IF(K15>L15,"Rights",IF(L15>K15,"Organisation","Both equal"))) | P15: =IF(B15="","",IFERROR(INDEX('Crosswalk IDs'!$E$2:$E$47,MATCH(B15,'Crosswalk IDs'!$A$2:$A$47,0)),"ID NOT IN CROSSWALK")) | R15: =IF(P15="","",IFERROR(INDEX(Lists!$F$2:$F$5,MATCH(P15,Lists!$E$2:$E$5,0)),"")) | T15: =IF(OR(Q15="",R15=""),"",IF(AND(MATCH(Q15,Lists!$A$2:$A$4,0)>MATCH(R15,Lists!$A$2:$A$4,0),S15=""),R15,Q15)) | U15: =IF(T15="","",MAX(1,H15-(MATCH(T15,Lists!$A$2:$A$4,0)-1))) | V15: =IF(U15="","",U15*I15) | W15: =IF(U15="","",U15*J15) | X15: =IF(U15="","",MAX(V15,W15)) | Y15: =IF(X15="","",CHOOSE(MAX(IF(X15>=16,4,IF(X15>=10,3,IF(X15>=5,2,1))),IF(OR(I15=5,AND(I15>=4,U15>=2)),3,1)),"Low","Medium","High","Critical"))
... D30: =IF(B30="","",IFERROR(INDEX('Crosswalk IDs'!$C$2:$C$47,MATCH(B30,'Crosswalk IDs'!$A$2:$A$47,0)),"ID NOT IN CROSSWALK")) | E30: =IF(B30="","",IFERROR(INDEX('Crosswalk IDs'!$D$2:$D$47,MATCH(B30,'Crosswalk IDs'!$A$2:$A$47,0)),"ID NOT IN CROSSWALK")) | K30: =IF(OR(H30="",I30=""),"",H30*I30) | L30: =IF(OR(H30="",J30=""),"",H30*J30) | M30: =IF(K30="","",MAX(K30,L30)) | N30: =IF(M30="","",IF(K30>L30,"Rights",IF(L30>K30,"Organisation","Both equal"))) | P30: =IF(B30="","",IFERROR(INDEX('Crosswalk IDs'!$E$2:$E$47,MATCH(B30,'Crosswalk IDs'!$A$2:$A$47,0)),"ID NOT IN CROSSWALK")) | R30: =IF(P30="","",IFERROR(INDEX(Lists!$F$2:$F$5,MATCH(P30,Lists!$E$2:$E$5,0)),"")) | T30: =IF(OR(Q30="",R30=""),"",IF(AND(MATCH(Q30,Lists!$A$2:$A$4,0)>MATCH(R30,Lists!$A$2:$A$4,0),S30=""),R30,Q30)) | U30: =IF(T30="","",MAX(1,H30-(MATCH(T30,Lists!$A$2:$A$4,0)-1))) | V30: =IF(U30="","",U30*I30) | W30: =IF(U30="","",U30*J30) | X30: =IF(U30="","",MAX(V30,W30)) | Y30: =IF(X30="","",CHOOSE(MAX(IF(X30>=16,4,IF(X30>=10,3,IF(X30>=5,2,1))),IF(OR(I30=5,AND(I30>=4,U30>=2)),3,1)),"Low","Medium","High","Critical"))

Sheet Scoring Methodology
A1: 1. Why two impact scales
A2: In enterprise risk management 'risk' means risk to the organisation. In the EU AI Act 'risk' means risk to the health, safety and fundamental rights of persons. They are different objects and can diverge: a system can be commercially low-risk and high-risk to the people it affects. The register therefore scores Rights Impact and Organisational Impact separately and shows which one drives the result.
A4: 2. Likelihood (next 12 months, in the system's operating context)
A5: Score | B5: Label | C5: Definition
A6: 1 | B6: Rare | C6: Not expected in the next 12 months. No comparable incident documented in the sector. Would need several independent control failures.
A7: 2 | B7: Unlikely | C7: Could occur. Isolated comparable incidents documented outside the sector or in a materially different use. Preventive controls are strong and tested.
A8: 3 | B8: Possible | C8: Plausible under normal operation; comparable incidents documented in the sector.
A9: 4 | B9: Likely | C9: Expected at least once in the next 12 months under current operation. Multiple documented comparable incidents, or a known weakness not yet treated.
A10: 5 | B10: Almost certain | C10: Occurring now or recurring routinely. Known and unremediated.
A12: 3. Rights Impact (harm to persons)
A13: Score | B13: Label | C13: Definition
A14: 1 | B14: Negligible | C14: No discernible adverse effect on any person; trivially reversible.
A15: 2 | B15: Minor | C15: Transient inconvenience or minor differential treatment that the person can reverse quickly without outside help.
A16: 3 | B16: Moderate | C16: Noticeable adverse effect on quality of service or treatment (delay, extra burden) that is reversible through complaint or appeal with effort; limited number of persons.
A17: 4 | B17: Major | C17: Material adverse effect on an individual's access to a service, employment, or legal standing, or discrimination on a protected ground; reversal is slow or difficult.
A18: 5 | B18: Severe | C18: Death or serious harm to health, loss of liberty, serious infringement of a fundamental right, or discrimination affecting many persons; effectively irreversible.
A20: 4. Organisational Impact (harm to the organisation)
A21: Score | B21: Label | C21: Definition
A22: 1 | B22: Negligible | C22: Handled inside the team; no external attention; within business-as-usual cost.
A23: 2 | B23: Minor | C23: Internal remediation project; no regulator or customer escalation.
A24: 3 | B24: Moderate | C24: Regulator information request, customer escalation or contractual remedy; funded remediation programme.
A25: 4 | B25: Major | C25: Formal enforcement step (corrective order, withdrawal or recall), loss of a key customer or of a certification, or a fine well below the statutory ceiling.
A26: 5 | B26: Severe | C26: Fine at or near the statutory ceiling (Art. 99(4): up to EUR 15m or 3% of worldwide turnover for operator obligations; Art. 99(3): EUR 35m / 7% for Art. 5; Art. 101: up to 3% / EUR 15m for GPAI providers), withdrawal of the product line from the Union market, or existential reputational damage.
A28: 5. Control effectiveness (rated on evidence of operation)
A29: Reduction | B29: Rating | C29: Definition
A30: 0 | B30: Not effective | C30: No control, or a documented control with no evidence it operates.
A31: 1 | B31: Partially effective | C31: Designed and implemented, but untested, or tested with known material gaps.
A32: 2 | B32: Largely effective | C32: Designed, implemented and tested within the last 12 months with only minor gaps.
A34: 6. Effectiveness cap from the crosswalk verdict
B35: Crosswalk ISO 42001 verdict | C35: Maximum effectiveness unless a written override cites a non-ISO control
B36: Substantially evidences | C36: Largely effective
B37: Partially evidences | C37: Partially effective
B38: Adjacent | C38: Not effective
B39: No coverage | C39: Not effective
A41: 7. Formulae
B42: Item | C42: Rule
B43: Rights score / Org score | C43: Likelihood x Rights Impact ; Likelihood x Organisational Impact
B44: Inherent score | C44: MAX(Rights score, Organisational score); driver column shows which one
B45: Residual likelihood | C45: MAX(1, Likelihood - reduction for the applied effectiveness)
B46: Residual score | C46: MAX(Residual likelihood x Rights Impact, Residual likelihood x Org Impact). Impacts are not reduced by controls in this version.
...

Sheet Lists
A1: Effectiveness | B1: Likelihood reduction | C1: Definition | E1: Crosswalk verdict | F1: Max effectiveness | H1: Treatment | J1: Affected party
A2: Not effective | B2: 0 | C2: No control, or a documented control with no evidence it operates. | E2: Substantially evidences | F2: Largely effective | H2: Mitigate | J2: individuals
A3: Partially effective | B3: 1 | C3: Designed and implemented, but untested, or tested with known material gaps. | E3: Partially evidences | F3: Partially effective | H3: Accept | J3: org
A4: Largely effective | B4: 2 | C4: Designed, implemented and tested within the last 12 months with only minor gaps. | E4: Adjacent | F4: Not effective | H4: Transfer | J4: both
E5: No coverage | F5: Not effective | H5: Avoid

Sheet Crosswalk IDs
A1: obligation_id | B1: eu_ai_act_article | C1: actor_role | D1: risk_tier | E1: iso42001_verdict | F1: nist_verdict
A2: PRV-HR-A09-RMS | B2: Art. 9(1)-(5) | C2: Provider | D2: High-risk | E2: Partially evidences | F2: Partially evidences
A3: PRV-HR-A09-TEST | B3: Art. 9(6)-(8) | C3: Provider | D3: High-risk | E3: Partially evidences | F3: Partially evidences
A4: PRV-HR-A09-VULN | B4: Art. 9(9) | C4: Provider | D4: High-risk | E4: Partially evidences | F4: Adjacent
A5: PRV-HR-A10-GOV | B5: Art. 10(1), 10(2)(a)-(e), 10(2)(h) | C5: Provider | D5: High-risk | E5: Substantially evidences | F5: Partially evidences
A6: PRV-HR-A10-BIAS | B6: Art. 10(2)(f)-(g), 10(3)-(4) | C6: Provider | D6: High-risk | E6: Partially evidences | F6: Partially evidences
A7: PRV-HR-A10-SCD | B7: Art. 4a (replacing deleted Art. 10(5)) | C7: Provider | D7: High-risk | E7: Adjacent | F7: Adjacent
A8: PRV-HR-A11-DOC | B8: Art. 11, Annex IV | C8: Provider | D8: High-risk | E8: Partially evidences | F8: Adjacent
A9: PRV-HR-A12-LOG | B9: Art. 12(1)-(2) (12(3) for Annex III 1(a)) | C9: Provider | D9: High-risk | E9: Partially evidences | F9: Adjacent
A10: PRV-HR-A13-IFU | B10: Art. 13(1)-(3) | C10: Provider | D10: High-risk | E10: Partially evidences | F10: Partially evidences
A11: PRV-HR-A14-OVS | B11: Art. 14(1)-(4) | C11: Provider | D11: High-risk | E11: Adjacent | F11: Partially evidences
A12: PRV-HR-A15-ACC | B12: Art. 15(1)-(4) | C12: Provider | D12: High-risk | E12: Partially evidences | F12: Partially evidences
... A47: GPP-GPS-A55-CYB | B47: Art. 55(1)(d) | C47: GPAI model provider | D47: GPAI with systemic risk | E47: Adjacent | F47: Partially evidences
